Traceback (most recent call last):
  File "/home/mjirka/anaconda3/lib/python3.9/site-packages/jupyter_cache/executors/utils.py", line 51, in single_nb_execution
    executenb(
  File "/home/mjirka/anaconda3/lib/python3.9/site-packages/nbclient/client.py", line 1204, in execute
    return NotebookClient(nb=nb, resources=resources, km=km, **kwargs).execute()
  File "/home/mjirka/anaconda3/lib/python3.9/site-packages/nbclient/util.py", line 84, in wrapped
    return just_run(coro(*args, **kwargs))
  File "/home/mjirka/anaconda3/lib/python3.9/site-packages/nbclient/util.py", line 62, in just_run
    return loop.run_until_complete(coro)
  File "/home/mjirka/anaconda3/lib/python3.9/asyncio/base_events.py", line 647, in run_until_complete
    return future.result()
  File "/home/mjirka/anaconda3/lib/python3.9/site-packages/nbclient/client.py", line 663, in async_execute
    await self.async_execute_cell(
  File "/home/mjirka/anaconda3/lib/python3.9/site-packages/nbclient/client.py", line 965, in async_execute_cell
    await self._check_raise_for_error(cell, cell_index, exec_reply)
  File "/home/mjirka/anaconda3/lib/python3.9/site-packages/nbclient/client.py", line 862, in _check_raise_for_error
    raise CellExecutionError.from_cell_and_msg(cell, exec_reply_content)
nbclient.exceptions.CellExecutionError: An error occurred while executing the following cell:
------------------
#
x = np.array([1, 2, 3, 4])
y = np.array([6, 5, 7, 10])
n = x.size

# predpokladame linearni aproximacni polynom y = kx + q
# minimum fukncionalu S najdeme pomoci derivace
# to vede na reseni soustavy lin. rovnic
# ze soustavy lin. rovnic vypocitame koeficienty k, q
# np.sum() = suma

# DOPLNIT
# A =
# b =
# DOPLNIT

# ziskame koeficienty
reseni = np.linalg.solve(A,b)
k = reseni[0]
q = reseni[1]

print('Parametr k: ',k)
print('Parametr q: ',q)

fig, ax = plt.subplots(figsize=(10,5))
ax.scatter(x,y,label='Namerena data')
ax.plot(x,k*x+q, color='C1', label='Aproximacni funkce y=kx+q')
ax.set_xlabel('x')
ax.set_ylabel('y')
ax.legend()
ax.set_title('Aproximace metodou nejmensich ctvercu')
------------------

[0;31m---------------------------------------------------------------------------[0m
[0;31mNameError[0m                                 Traceback (most recent call last)
[0;32m/tmp/ipykernel_15462/138282949.py[0m in [0;36m<module>[0;34m[0m
[1;32m     16[0m [0;34m[0m[0m
[1;32m     17[0m [0;31m# ziskame koeficienty[0m[0;34m[0m[0;34m[0m[0m
[0;32m---> 18[0;31m [0mreseni[0m [0;34m=[0m [0mnp[0m[0;34m.[0m[0mlinalg[0m[0;34m.[0m[0msolve[0m[0;34m([0m[0mA[0m[0;34m,[0m[0mb[0m[0;34m)[0m[0;34m[0m[0;34m[0m[0m
[0m[1;32m     19[0m [0mk[0m [0;34m=[0m [0mreseni[0m[0;34m[[0m[0;36m0[0m[0;34m][0m[0;34m[0m[0;34m[0m[0m
[1;32m     20[0m [0mq[0m [0;34m=[0m [0mreseni[0m[0;34m[[0m[0;36m1[0m[0;34m][0m[0;34m[0m[0;34m[0m[0m

[0;31mNameError[0m: name 'A' is not defined
NameError: name 'A' is not defined

